2021-01-04 20:34:44,607 (28168/MainThread) pgcli.main INFO - No default pager found in environment. Using os default pager
2021-01-04 20:34:44,607 (28168/MainThread) pgcli.main WARNING - import keyring failed: ModuleNotFoundError("No module named 'keyring'").
2021-01-04 20:34:44,615 (28168/MainThread) pgcli.main ERROR - traceback: 'Traceback (most recent call last):\n  File "/usr/local/Cellar/pgcli/3.1.0/libexec/lib/python3.9/site-packages/pgcli/main.py", line 582, in connect\n    raise e\n  File "/usr/local/Cellar/pgcli/3.1.0/libexec/lib/python3.9/site-packages/pgcli/main.py", line 569, in connect\n    pgexecute = PGExecute(database, user, passwd, host, port, dsn, **kwargs)\n  File "/usr/local/Cellar/pgcli/3.1.0/libexec/lib/python3.9/site-packages/pgcli/pgexecute.py", line 214, in __init__\n    self.connect(database, user, password, host, port, dsn, **kwargs)\n  File "/usr/local/Cellar/pgcli/3.1.0/libexec/lib/python3.9/site-packages/pgcli/pgexecute.py", line 254, in connect\n    conn = psycopg2.connect(**conn_params)\n  File "/usr/local/Cellar/pgcli/3.1.0/libexec/lib/python3.9/site-packages/psycopg2/__init__.py", line 127, in connect\n    conn = _connect(dsn, connection_factory=connection_factory, **kwasync)\n  File "/usr/local/Cellar/pgcli/3.1.0/libexec/lib/python3.9/site-packages/pgcli/pgexecute.py", line 39, in _wait_select\n    state = conn.poll()\npsycopg2.OperationalError: FATAL:  role "kevin-mbp" does not exist\n\n'
2021-01-04 20:34:55,491 (28171/MainThread) pgcli.main INFO - No default pager found in environment. Using os default pager
2021-01-04 20:34:55,492 (28171/MainThread) pgcli.main WARNING - import keyring failed: ModuleNotFoundError("No module named 'keyring'").
2021-01-04 21:10:41,721 (28673/MainThread) pgcli.main INFO - No default pager found in environment. Using os default pager
2021-01-04 21:10:41,721 (28673/MainThread) pgcli.main WARNING - import keyring failed: ModuleNotFoundError("No module named 'keyring'").
2021-01-04 21:10:41,730 (28673/MainThread) pgcli.main ERROR - traceback: 'Traceback (most recent call last):\n  File "/usr/local/Cellar/pgcli/3.1.0/libexec/lib/python3.9/site-packages/pgcli/main.py", line 582, in connect\n    raise e\n  File "/usr/local/Cellar/pgcli/3.1.0/libexec/lib/python3.9/site-packages/pgcli/main.py", line 569, in connect\n    pgexecute = PGExecute(database, user, passwd, host, port, dsn, **kwargs)\n  File "/usr/local/Cellar/pgcli/3.1.0/libexec/lib/python3.9/site-packages/pgcli/pgexecute.py", line 214, in __init__\n    self.connect(database, user, password, host, port, dsn, **kwargs)\n  File "/usr/local/Cellar/pgcli/3.1.0/libexec/lib/python3.9/site-packages/pgcli/pgexecute.py", line 254, in connect\n    conn = psycopg2.connect(**conn_params)\n  File "/usr/local/Cellar/pgcli/3.1.0/libexec/lib/python3.9/site-packages/psycopg2/__init__.py", line 127, in connect\n    conn = _connect(dsn, connection_factory=connection_factory, **kwasync)\n  File "/usr/local/Cellar/pgcli/3.1.0/libexec/lib/python3.9/site-packages/pgcli/pgexecute.py", line 39, in _wait_select\n    state = conn.poll()\npsycopg2.OperationalError: FATAL:  role "kevin-mbp" does not exist\n\n'
2021-01-04 21:11:19,401 (28681/MainThread) pgcli.main INFO - No default pager found in environment. Using os default pager
2021-01-04 21:11:19,401 (28681/MainThread) pgcli.main WARNING - import keyring failed: ModuleNotFoundError("No module named 'keyring'").
2021-01-04 21:11:19,407 (28681/MainThread) pgcli.main ERROR - traceback: 'Traceback (most recent call last):\n  File "/usr/local/Cellar/pgcli/3.1.0/libexec/lib/python3.9/site-packages/pgcli/main.py", line 582, in connect\n    raise e\n  File "/usr/local/Cellar/pgcli/3.1.0/libexec/lib/python3.9/site-packages/pgcli/main.py", line 569, in connect\n    pgexecute = PGExecute(database, user, passwd, host, port, dsn, **kwargs)\n  File "/usr/local/Cellar/pgcli/3.1.0/libexec/lib/python3.9/site-packages/pgcli/pgexecute.py", line 214, in __init__\n    self.connect(database, user, password, host, port, dsn, **kwargs)\n  File "/usr/local/Cellar/pgcli/3.1.0/libexec/lib/python3.9/site-packages/pgcli/pgexecute.py", line 254, in connect\n    conn = psycopg2.connect(**conn_params)\n  File "/usr/local/Cellar/pgcli/3.1.0/libexec/lib/python3.9/site-packages/psycopg2/__init__.py", line 127, in connect\n    conn = _connect(dsn, connection_factory=connection_factory, **kwasync)\n  File "/usr/local/Cellar/pgcli/3.1.0/libexec/lib/python3.9/site-packages/pgcli/pgexecute.py", line 39, in _wait_select\n    state = conn.poll()\npsycopg2.OperationalError: FATAL:  role "kevin-mbp" does not exist\n\n'
2021-01-04 21:11:30,168 (28686/MainThread) pgcli.main INFO - No default pager found in environment. Using os default pager
2021-01-04 21:11:30,169 (28686/MainThread) pgcli.main WARNING - import keyring failed: ModuleNotFoundError("No module named 'keyring'").
2021-01-04 21:26:51,419 (29506/MainThread) pgcli.main INFO - No default pager found in environment. Using os default pager
2021-01-04 21:26:51,419 (29506/MainThread) pgcli.main WARNING - import keyring failed: ModuleNotFoundError("No module named 'keyring'").
2021-01-04 21:36:12,534 (29828/MainThread) pgcli.main INFO - No default pager found in environment. Using os default pager
2021-01-04 21:36:12,534 (29828/MainThread) pgcli.main WARNING - import keyring failed: ModuleNotFoundError("No module named 'keyring'").
2021-01-04 21:45:42,290 (30092/MainThread) pgcli.main INFO - No default pager found in environment. Using os default pager
2021-01-04 21:45:42,290 (30092/MainThread) pgcli.main WARNING - import keyring failed: ModuleNotFoundError("No module named 'keyring'").
2021-01-04 21:49:46,497 (30162/MainThread) pgcli.main INFO - No default pager found in environment. Using os default pager
2021-01-04 21:49:46,499 (30162/MainThread) pgcli.main WARNING - import keyring failed: ModuleNotFoundError("No module named 'keyring'").
2021-01-04 21:50:06,070 (30162/MainThread) pgcli.pgexecute ERROR - sql: 'drop sequence todo_todo_id_seq', error: DependentObjectsStillExist('cannot drop sequence todo_todo_id_seq because other objects depend on it\nDETAIL:  default value for column todo_id of table todo depends on sequence todo_todo_id_seq\nHINT:  Use DROP ... CASCADE to drop the dependent objects too.\n')
2021-01-04 21:50:06,072 (30162/MainThread) pgcli.pgexecute ERROR - traceback: 'Traceback (most recent call last):\n  File "/usr/local/Cellar/pgcli/3.1.0/libexec/lib/python3.9/site-packages/pgcli/pgexecute.py", line 409, in run\n    yield self.execute_normal_sql(sql) + (sql, True, False)\n  File "/usr/local/Cellar/pgcli/3.1.0/libexec/lib/python3.9/site-packages/pgcli/pgexecute.py", line 444, in execute_normal_sql\n    cur.execute(split_sql)\npsycopg2.errors.DependentObjectsStillExist: cannot drop sequence todo_todo_id_seq because other objects depend on it\nDETAIL:  default value for column todo_id of table todo depends on sequence todo_todo_id_seq\nHINT:  Use DROP ... CASCADE to drop the dependent objects too.\n\n'
2021-01-04 21:50:18,166 (30162/MainThread) pgcli.pgexecute ERROR - sql: 'drop sequence Cascade todo_todo_id_seq', error: SyntaxError('syntax error at or near "todo_todo_id_seq"\nLINE 1: drop sequence Cascade todo_todo_id_seq\n                              ^\n')
2021-01-04 21:50:18,166 (30162/MainThread) pgcli.pgexecute ERROR - traceback: 'Traceback (most recent call last):\n  File "/usr/local/Cellar/pgcli/3.1.0/libexec/lib/python3.9/site-packages/pgcli/pgexecute.py", line 409, in run\n    yield self.execute_normal_sql(sql) + (sql, True, False)\n  File "/usr/local/Cellar/pgcli/3.1.0/libexec/lib/python3.9/site-packages/pgcli/pgexecute.py", line 444, in execute_normal_sql\n    cur.execute(split_sql)\npsycopg2.errors.SyntaxError: syntax error at or near "todo_todo_id_seq"\nLINE 1: drop sequence Cascade todo_todo_id_seq\n                              ^\n\n'
2021-01-04 22:12:19,875 (30162/MainThread) pgcli.pgexecute ERROR - sql: 'sele', error: SyntaxError('syntax error at or near "sele"\nLINE 1: sele\n        ^\n')
2021-01-04 22:12:19,875 (30162/MainThread) pgcli.pgexecute ERROR - traceback: 'Traceback (most recent call last):\n  File "/usr/local/Cellar/pgcli/3.1.0/libexec/lib/python3.9/site-packages/pgcli/pgexecute.py", line 409, in run\n    yield self.execute_normal_sql(sql) + (sql, True, False)\n  File "/usr/local/Cellar/pgcli/3.1.0/libexec/lib/python3.9/site-packages/pgcli/pgexecute.py", line 444, in execute_normal_sql\n    cur.execute(split_sql)\npsycopg2.errors.SyntaxError: syntax error at or near "sele"\nLINE 1: sele\n        ^\n\n'
2021-01-05 11:26:39,336 (759/MainThread) pgcli.main INFO - No default pager found in environment. Using os default pager
2021-01-05 11:26:39,337 (759/MainThread) pgcli.main WARNING - import keyring failed: ModuleNotFoundError("No module named 'keyring'").
2021-01-05 11:26:39,346 (759/MainThread) pgcli.main ERROR - traceback: 'Traceback (most recent call last):\n  File "/usr/local/Cellar/pgcli/3.1.0/libexec/lib/python3.9/site-packages/pgcli/main.py", line 582, in connect\n    raise e\n  File "/usr/local/Cellar/pgcli/3.1.0/libexec/lib/python3.9/site-packages/pgcli/main.py", line 569, in connect\n    pgexecute = PGExecute(database, user, passwd, host, port, dsn, **kwargs)\n  File "/usr/local/Cellar/pgcli/3.1.0/libexec/lib/python3.9/site-packages/pgcli/pgexecute.py", line 214, in __init__\n    self.connect(database, user, password, host, port, dsn, **kwargs)\n  File "/usr/local/Cellar/pgcli/3.1.0/libexec/lib/python3.9/site-packages/pgcli/pgexecute.py", line 254, in connect\n    conn = psycopg2.connect(**conn_params)\n  File "/usr/local/Cellar/pgcli/3.1.0/libexec/lib/python3.9/site-packages/psycopg2/__init__.py", line 127, in connect\n    conn = _connect(dsn, connection_factory=connection_factory, **kwasync)\npsycopg2.OperationalError: could not connect to server: No such file or directory\n\tIs the server running locally and accepting\n\tconnections on Unix domain socket "/tmp/.s.PGSQL.5432"?\n\n'
2021-01-05 12:17:22,434 (1362/MainThread) pgcli.main INFO - No default pager found in environment. Using os default pager
2021-01-05 12:17:22,435 (1362/MainThread) pgcli.main WARNING - import keyring failed: ModuleNotFoundError("No module named 'keyring'").
2021-01-05 12:17:34,954 (1362/MainThread) pgcli.pgexecute ERROR - sql: '/l', error: SyntaxError('syntax error at or near "/"\nLINE 1: /l\n        ^\n')
2021-01-05 12:17:34,955 (1362/MainThread) pgcli.pgexecute ERROR - traceback: 'Traceback (most recent call last):\n  File "/usr/local/Cellar/pgcli/3.1.0/libexec/lib/python3.9/site-packages/pgcli/pgexecute.py", line 409, in run\n    yield self.execute_normal_sql(sql) + (sql, True, False)\n  File "/usr/local/Cellar/pgcli/3.1.0/libexec/lib/python3.9/site-packages/pgcli/pgexecute.py", line 444, in execute_normal_sql\n    cur.execute(split_sql)\npsycopg2.errors.SyntaxError: syntax error at or near "/"\nLINE 1: /l\n        ^\n\n'
2021-01-05 12:17:56,961 (1362/MainThread) pgcli.pgexecute ERROR - sql: 'select * from information_schema', error: UndefinedTable('relation "information_schema" does not exist\nLINE 1: select * from information_schema\n                      ^\n')
2021-01-05 12:17:56,961 (1362/MainThread) pgcli.pgexecute ERROR - traceback: 'Traceback (most recent call last):\n  File "/usr/local/Cellar/pgcli/3.1.0/libexec/lib/python3.9/site-packages/pgcli/pgexecute.py", line 409, in run\n    yield self.execute_normal_sql(sql) + (sql, True, False)\n  File "/usr/local/Cellar/pgcli/3.1.0/libexec/lib/python3.9/site-packages/pgcli/pgexecute.py", line 444, in execute_normal_sql\n    cur.execute(split_sql)\npsycopg2.errors.UndefinedTable: relation "information_schema" does not exist\nLINE 1: select * from information_schema\n                      ^\n\n'
2021-01-05 12:19:15,275 (1362/MainThread) pgcli.pgexecute ERROR - sql: 'q', error: SyntaxError('syntax error at or near "q"\nLINE 1: q\n        ^\n')
2021-01-05 12:19:15,275 (1362/MainThread) pgcli.pgexecute ERROR - traceback: 'Traceback (most recent call last):\n  File "/usr/local/Cellar/pgcli/3.1.0/libexec/lib/python3.9/site-packages/pgcli/pgexecute.py", line 409, in run\n    yield self.execute_normal_sql(sql) + (sql, True, False)\n  File "/usr/local/Cellar/pgcli/3.1.0/libexec/lib/python3.9/site-packages/pgcli/pgexecute.py", line 444, in execute_normal_sql\n    cur.execute(split_sql)\npsycopg2.errors.SyntaxError: syntax error at or near "q"\nLINE 1: q\n        ^\n\n'
2021-01-05 12:22:15,337 (1362/MainThread) pgcli.pgexecute ERROR - sql: 'upda', error: SyntaxError('syntax error at or near "upda"\nLINE 1: upda\n        ^\n')
2021-01-05 12:22:15,338 (1362/MainThread) pgcli.pgexecute ERROR - traceback: 'Traceback (most recent call last):\n  File "/usr/local/Cellar/pgcli/3.1.0/libexec/lib/python3.9/site-packages/pgcli/pgexecute.py", line 409, in run\n    yield self.execute_normal_sql(sql) + (sql, True, False)\n  File "/usr/local/Cellar/pgcli/3.1.0/libexec/lib/python3.9/site-packages/pgcli/pgexecute.py", line 444, in execute_normal_sql\n    cur.execute(split_sql)\npsycopg2.errors.SyntaxError: syntax error at or near "upda"\nLINE 1: upda\n        ^\n\n'
2021-01-05 12:22:53,004 (1362/MainThread) pgcli.pgexecute ERROR - sql: 'update box_table SELECT box_id=a3b9f6a2-4bf8-11eb-ab55-cbaaf5b7127e', error: SyntaxError('syntax error at or near "SELECT"\nLINE 1: update box_table SELECT box_id=a3b9f6a2-4bf8-11eb-ab55-cbaaf...\n                         ^\n')
2021-01-05 12:22:53,005 (1362/MainThread) pgcli.pgexecute ERROR - traceback: 'Traceback (most recent call last):\n  File "/usr/local/Cellar/pgcli/3.1.0/libexec/lib/python3.9/site-packages/pgcli/pgexecute.py", line 409, in run\n    yield self.execute_normal_sql(sql) + (sql, True, False)\n  File "/usr/local/Cellar/pgcli/3.1.0/libexec/lib/python3.9/site-packages/pgcli/pgexecute.py", line 444, in execute_normal_sql\n    cur.execute(split_sql)\npsycopg2.errors.SyntaxError: syntax error at or near "SELECT"\nLINE 1: update box_table SELECT box_id=a3b9f6a2-4bf8-11eb-ab55-cbaaf...\n                         ^\n\n'
2021-01-05 12:23:17,623 (1362/MainThread) pgcli.pgexecute ERROR - sql: 'update box_table(box_finished_timestamp) values(NOW()) where  box_id=a3b9f6a2-4bf8-11eb-ab55-cbaaf5b7127e', error: SyntaxError('syntax error at or near "("\nLINE 1: update box_table(box_finished_timestamp) values(NOW()) where...\n                        ^\n')
2021-01-05 12:23:17,623 (1362/MainThread) pgcli.pgexecute ERROR - traceback: 'Traceback (most recent call last):\n  File "/usr/local/Cellar/pgcli/3.1.0/libexec/lib/python3.9/site-packages/pgcli/pgexecute.py", line 409, in run\n    yield self.execute_normal_sql(sql) + (sql, True, False)\n  File "/usr/local/Cellar/pgcli/3.1.0/libexec/lib/python3.9/site-packages/pgcli/pgexecute.py", line 444, in execute_normal_sql\n    cur.execute(split_sql)\npsycopg2.errors.SyntaxError: syntax error at or near "("\nLINE 1: update box_table(box_finished_timestamp) values(NOW()) where...\n                        ^\n\n'
2021-01-05 12:23:30,614 (1362/MainThread) pgcli.pgexecute ERROR - sql: 'update box_table (box_finished_timestamp) values(NOW()) where  box_id=a3b9f6a2-4bf8-11eb-ab55-cbaaf5b7127e', error: SyntaxError('syntax error at or near "("\nLINE 1: update box_table (box_finished_timestamp) values(NOW()) wher...\n                         ^\n')
2021-01-05 12:23:30,615 (1362/MainThread) pgcli.pgexecute ERROR - traceback: 'Traceback (most recent call last):\n  File "/usr/local/Cellar/pgcli/3.1.0/libexec/lib/python3.9/site-packages/pgcli/pgexecute.py", line 409, in run\n    yield self.execute_normal_sql(sql) + (sql, True, False)\n  File "/usr/local/Cellar/pgcli/3.1.0/libexec/lib/python3.9/site-packages/pgcli/pgexecute.py", line 444, in execute_normal_sql\n    cur.execute(split_sql)\npsycopg2.errors.SyntaxError: syntax error at or near "("\nLINE 1: update box_table (box_finished_timestamp) values(NOW()) wher...\n                         ^\n\n'
2021-01-05 12:23:42,509 (1362/MainThread) pgcli.pgexecute ERROR - sql: 'update box_table box_finished_timestamp values(NOW()) where  box_id=a3b9f6a2-4bf8-11eb-ab55-cbaaf5b7127e', error: SyntaxError('syntax error at or near "values"\nLINE 1: update box_table box_finished_timestamp values(NOW()) where ...\n                                                ^\n')
2021-01-05 12:23:42,510 (1362/MainThread) pgcli.pgexecute ERROR - traceback: 'Traceback (most recent call last):\n  File "/usr/local/Cellar/pgcli/3.1.0/libexec/lib/python3.9/site-packages/pgcli/pgexecute.py", line 409, in run\n    yield self.execute_normal_sql(sql) + (sql, True, False)\n  File "/usr/local/Cellar/pgcli/3.1.0/libexec/lib/python3.9/site-packages/pgcli/pgexecute.py", line 444, in execute_normal_sql\n    cur.execute(split_sql)\npsycopg2.errors.SyntaxError: syntax error at or near "values"\nLINE 1: update box_table box_finished_timestamp values(NOW()) where ...\n                                                ^\n\n'
2021-01-05 12:24:11,554 (1362/MainThread) pgcli.pgexecute ERROR - sql: 'update box_table set  box_finished_timestamp values(NOW()) where  box_id=a3b9f6a2-4bf8-11eb-ab55-cbaaf5b7127e', error: SyntaxError('syntax error at or near "values"\nLINE 1: update box_table set  box_finished_timestamp values(NOW()) w...\n                                                     ^\n')
2021-01-05 12:24:11,554 (1362/MainThread) pgcli.pgexecute ERROR - traceback: 'Traceback (most recent call last):\n  File "/usr/local/Cellar/pgcli/3.1.0/libexec/lib/python3.9/site-packages/pgcli/pgexecute.py", line 409, in run\n    yield self.execute_normal_sql(sql) + (sql, True, False)\n  File "/usr/local/Cellar/pgcli/3.1.0/libexec/lib/python3.9/site-packages/pgcli/pgexecute.py", line 444, in execute_normal_sql\n    cur.execute(split_sql)\npsycopg2.errors.SyntaxError: syntax error at or near "values"\nLINE 1: update box_table set  box_finished_timestamp values(NOW()) w...\n                                                     ^\n\n'
2021-01-05 12:24:39,903 (1362/MainThread) pgcli.pgexecute ERROR - sql: 'update box_table set  box_finished_timestamp=NOW() where  box_id=a3b9f6a2-4bf8-11eb-ab55-cbaaf5b7127e', error: SyntaxError('syntax error at or near "bf8"\nLINE 1: ..._finished_timestamp=NOW() where  box_id=a3b9f6a2-4bf8-11eb-a...\n                                                             ^\n')
2021-01-05 12:24:39,903 (1362/MainThread) pgcli.pgexecute ERROR - traceback: 'Traceback (most recent call last):\n  File "/usr/local/Cellar/pgcli/3.1.0/libexec/lib/python3.9/site-packages/pgcli/pgexecute.py", line 409, in run\n    yield self.execute_normal_sql(sql) + (sql, True, False)\n  File "/usr/local/Cellar/pgcli/3.1.0/libexec/lib/python3.9/site-packages/pgcli/pgexecute.py", line 444, in execute_normal_sql\n    cur.execute(split_sql)\npsycopg2.errors.SyntaxError: syntax error at or near "bf8"\nLINE 1: ..._finished_timestamp=NOW() where  box_id=a3b9f6a2-4bf8-11eb-a...\n                                                             ^\n\n'
2021-01-06 16:58:31,637 (3239/MainThread) pgcli.main INFO - No default pager found in environment. Using os default pager
2021-01-06 16:58:31,637 (3239/MainThread) pgcli.main WARNING - import keyring failed: ModuleNotFoundError("No module named 'keyring'").
2021-01-07 17:36:01,981 (1883/MainThread) pgcli.main INFO - No default pager found in environment. Using os default pager
2021-01-07 17:36:01,981 (1883/MainThread) pgcli.main WARNING - import keyring failed: ModuleNotFoundError("No module named 'keyring'").
2021-01-07 17:36:01,990 (1883/MainThread) pgcli.main ERROR - traceback: 'Traceback (most recent call last):\n  File "/usr/local/Cellar/pgcli/3.1.0/libexec/lib/python3.9/site-packages/pgcli/main.py", line 582, in connect\n    raise e\n  File "/usr/local/Cellar/pgcli/3.1.0/libexec/lib/python3.9/site-packages/pgcli/main.py", line 569, in connect\n    pgexecute = PGExecute(database, user, passwd, host, port, dsn, **kwargs)\n  File "/usr/local/Cellar/pgcli/3.1.0/libexec/lib/python3.9/site-packages/pgcli/pgexecute.py", line 214, in __init__\n    self.connect(database, user, password, host, port, dsn, **kwargs)\n  File "/usr/local/Cellar/pgcli/3.1.0/libexec/lib/python3.9/site-packages/pgcli/pgexecute.py", line 254, in connect\n    conn = psycopg2.connect(**conn_params)\n  File "/usr/local/Cellar/pgcli/3.1.0/libexec/lib/python3.9/site-packages/psycopg2/__init__.py", line 127, in connect\n    conn = _connect(dsn, connection_factory=connection_factory, **kwasync)\npsycopg2.OperationalError: could not connect to server: No such file or directory\n\tIs the server running locally and accepting\n\tconnections on Unix domain socket "/tmp/.s.PGSQL.5432"?\n\n'
2021-01-07 17:38:36,799 (1913/MainThread) pgcli.main INFO - No default pager found in environment. Using os default pager
2021-01-07 17:38:36,800 (1913/MainThread) pgcli.main WARNING - import keyring failed: ModuleNotFoundError("No module named 'keyring'").
2021-01-10 12:28:28,838 (9152/MainThread) pgcli.main INFO - No default pager found in environment. Using os default pager
2021-01-10 12:28:28,839 (9152/MainThread) pgcli.main WARNING - import keyring failed: ModuleNotFoundError("No module named 'keyring'").
2021-01-10 12:28:33,320 (9152/MainThread) pgcli.pgexecute ERROR - sql: 'ls', error: SyntaxError('syntax error at or near "ls"\nLINE 1: ls\n        ^\n')
2021-01-10 12:28:33,322 (9152/MainThread) pgcli.pgexecute ERROR - traceback: 'Traceback (most recent call last):\n  File "/usr/local/Cellar/pgcli/3.1.0/libexec/lib/python3.9/site-packages/pgcli/pgexecute.py", line 409, in run\n    yield self.execute_normal_sql(sql) + (sql, True, False)\n  File "/usr/local/Cellar/pgcli/3.1.0/libexec/lib/python3.9/site-packages/pgcli/pgexecute.py", line 444, in execute_normal_sql\n    cur.execute(split_sql)\npsycopg2.errors.SyntaxError: syntax error at or near "ls"\nLINE 1: ls\n        ^\n\n'
2021-01-11 20:46:45,231 (18970/MainThread) pgcli.main INFO - No default pager found in environment. Using os default pager
2021-01-11 20:46:45,231 (18970/MainThread) pgcli.main WARNING - import keyring failed: ModuleNotFoundError("No module named 'keyring'").
2021-01-11 20:46:49,171 (18970/MainThread) pgcli.pgexecute ERROR - sql: 'q', error: SyntaxError('syntax error at or near "q"\nLINE 1: q\n        ^\n')
2021-01-11 20:46:49,172 (18970/MainThread) pgcli.pgexecute ERROR - traceback: 'Traceback (most recent call last):\n  File "/usr/local/Cellar/pgcli/3.1.0/libexec/lib/python3.9/site-packages/pgcli/pgexecute.py", line 409, in run\n    yield self.execute_normal_sql(sql) + (sql, True, False)\n  File "/usr/local/Cellar/pgcli/3.1.0/libexec/lib/python3.9/site-packages/pgcli/pgexecute.py", line 444, in execute_normal_sql\n    cur.execute(split_sql)\npsycopg2.errors.SyntaxError: syntax error at or near "q"\nLINE 1: q\n        ^\n\n'
2021-01-13 13:36:31,895 (13497/MainThread) pgcli.main INFO - No default pager found in environment. Using os default pager
2021-01-13 13:36:31,896 (13497/MainThread) pgcli.main WARNING - import keyring failed: ModuleNotFoundError("No module named 'keyring'").
2021-01-13 13:36:34,919 (13497/MainThread) pgcli.pgexecute ERROR - sql: '/l', error: SyntaxError('syntax error at or near "/"\nLINE 1: /l\n        ^\n')
2021-01-13 13:36:34,966 (13497/MainThread) pgcli.pgexecute ERROR - traceback: 'Traceback (most recent call last):\n  File "/usr/local/Cellar/pgcli/3.1.0/libexec/lib/python3.9/site-packages/pgcli/pgexecute.py", line 409, in run\n    yield self.execute_normal_sql(sql) + (sql, True, False)\n  File "/usr/local/Cellar/pgcli/3.1.0/libexec/lib/python3.9/site-packages/pgcli/pgexecute.py", line 444, in execute_normal_sql\n    cur.execute(split_sql)\npsycopg2.errors.SyntaxError: syntax error at or near "/"\nLINE 1: /l\n        ^\n\n'
2021-01-13 13:36:36,901 (13497/MainThread) pgcli.pgexecute ERROR - sql: '/d', error: SyntaxError('syntax error at or near "/"\nLINE 1: /d\n        ^\n')
2021-01-13 13:36:36,902 (13497/MainThread) pgcli.pgexecute ERROR - traceback: 'Traceback (most recent call last):\n  File "/usr/local/Cellar/pgcli/3.1.0/libexec/lib/python3.9/site-packages/pgcli/pgexecute.py", line 409, in run\n    yield self.execute_normal_sql(sql) + (sql, True, False)\n  File "/usr/local/Cellar/pgcli/3.1.0/libexec/lib/python3.9/site-packages/pgcli/pgexecute.py", line 444, in execute_normal_sql\n    cur.execute(split_sql)\npsycopg2.errors.SyntaxError: syntax error at or near "/"\nLINE 1: /d\n        ^\n\n'
2021-01-13 13:36:39,077 (13497/MainThread) pgcli.pgexecute ERROR - sql: '\\t', error: SyntaxError('syntax error at or near "\\"\nLINE 1: \\t\n        ^\n')
2021-01-13 13:36:39,077 (13497/MainThread) pgcli.pgexecute ERROR - traceback: 'Traceback (most recent call last):\n  File "/usr/local/Cellar/pgcli/3.1.0/libexec/lib/python3.9/site-packages/pgcli/pgexecute.py", line 409, in run\n    yield self.execute_normal_sql(sql) + (sql, True, False)\n  File "/usr/local/Cellar/pgcli/3.1.0/libexec/lib/python3.9/site-packages/pgcli/pgexecute.py", line 444, in execute_normal_sql\n    cur.execute(split_sql)\npsycopg2.errors.SyntaxError: syntax error at or near "\\"\nLINE 1: \\t\n        ^\n\n'
2021-01-13 13:39:58,665 (13497/MainThread) pgcli.pgexecute ERROR - sql: 'select * from bat', error: UndefinedTable('relation "bat" does not exist\nLINE 1: select * from bat\n                      ^\n')
2021-01-13 13:39:58,666 (13497/MainThread) pgcli.pgexecute ERROR - traceback: 'Traceback (most recent call last):\n  File "/usr/local/Cellar/pgcli/3.1.0/libexec/lib/python3.9/site-packages/pgcli/pgexecute.py", line 409, in run\n    yield self.execute_normal_sql(sql) + (sql, True, False)\n  File "/usr/local/Cellar/pgcli/3.1.0/libexec/lib/python3.9/site-packages/pgcli/pgexecute.py", line 444, in execute_normal_sql\n    cur.execute(split_sql)\npsycopg2.errors.UndefinedTable: relation "bat" does not exist\nLINE 1: select * from bat\n                      ^\n\n'
2021-01-13 13:42:30,378 (13687/MainThread) pgcli.main INFO - No default pager found in environment. Using os default pager
2021-01-13 13:42:30,379 (13687/MainThread) pgcli.main WARNING - import keyring failed: ModuleNotFoundError("No module named 'keyring'").
2021-01-15 14:54:09,072 (3803/MainThread) pgcli.main INFO - No default pager found in environment. Using os default pager
2021-01-15 14:54:09,073 (3803/MainThread) pgcli.main WARNING - import keyring failed: ModuleNotFoundError("No module named 'keyring'").
2021-01-15 15:00:33,125 (4273/MainThread) pgcli.main INFO - No default pager found in environment. Using os default pager
2021-01-15 15:00:33,126 (4273/MainThread) pgcli.main WARNING - import keyring failed: ModuleNotFoundError("No module named 'keyring'").
2021-01-15 15:01:55,082 (4273/MainThread) pgcli.pgexecute ERROR - sql: 'q', error: SyntaxError('syntax error at or near "q"\nLINE 1: q\n        ^\n')
2021-01-15 15:01:55,129 (4273/MainThread) pgcli.pgexecute ERROR - traceback: 'Traceback (most recent call last):\n  File "/usr/local/Cellar/pgcli/3.1.0/libexec/lib/python3.9/site-packages/pgcli/pgexecute.py", line 409, in run\n    yield self.execute_normal_sql(sql) + (sql, True, False)\n  File "/usr/local/Cellar/pgcli/3.1.0/libexec/lib/python3.9/site-packages/pgcli/pgexecute.py", line 444, in execute_normal_sql\n    cur.execute(split_sql)\npsycopg2.errors.SyntaxError: syntax error at or near "q"\nLINE 1: q\n        ^\n\n'
2021-01-15 15:12:50,753 (4472/MainThread) pgcli.main INFO - No default pager found in environment. Using os default pager
2021-01-15 15:12:50,753 (4472/MainThread) pgcli.main WARNING - import keyring failed: ModuleNotFoundError("No module named 'keyring'").
2021-01-18 21:35:12,343 (50351/MainThread) pgcli.main INFO - No default pager found in environment. Using os default pager
2021-01-18 21:35:12,344 (50351/MainThread) pgcli.main WARNING - import keyring failed: ModuleNotFoundError("No module named 'keyring'").
2021-02-02 16:27:03,590 (22328/MainThread) pgcli.main INFO - No default pager found in environment. Using os default pager
2021-02-02 16:27:03,591 (22328/MainThread) pgcli.main WARNING - import keyring failed: ModuleNotFoundError("No module named 'keyring'").
2021-02-02 16:27:11,695 (22328/MainThread) pgcli.pgexecute ERROR - sql: 'sel', error: SyntaxError('syntax error at or near "sel"\nLINE 1: sel\n        ^\n')
2021-02-02 16:27:11,738 (22328/MainThread) pgcli.pgexecute ERROR - traceback: 'Traceback (most recent call last):\n  File "/usr/local/Cellar/pgcli/3.1.0/libexec/lib/python3.9/site-packages/pgcli/pgexecute.py", line 409, in run\n    yield self.execute_normal_sql(sql) + (sql, True, False)\n  File "/usr/local/Cellar/pgcli/3.1.0/libexec/lib/python3.9/site-packages/pgcli/pgexecute.py", line 444, in execute_normal_sql\n    cur.execute(split_sql)\npsycopg2.errors.SyntaxError: syntax error at or near "sel"\nLINE 1: sel\n        ^\n\n'
2021-02-02 16:29:52,849 (22328/MainThread) pgcli.pgexecute ERROR - sql: 'select * from serial_barcode_table order by entry_added_timestamp desc limit 10', error: UndefinedColumn('column "entry_added_timestamp" does not exist\nLINE 1: select * from serial_barcode_table order by entry_added_time...\n                                                    ^\n')
2021-02-02 16:29:52,850 (22328/MainThread) pgcli.pgexecute ERROR - traceback: 'Traceback (most recent call last):\n  File "/usr/local/Cellar/pgcli/3.1.0/libexec/lib/python3.9/site-packages/pgcli/pgexecute.py", line 409, in run\n    yield self.execute_normal_sql(sql) + (sql, True, False)\n  File "/usr/local/Cellar/pgcli/3.1.0/libexec/lib/python3.9/site-packages/pgcli/pgexecute.py", line 444, in execute_normal_sql\n    cur.execute(split_sql)\npsycopg2.errors.UndefinedColumn: column "entry_added_timestamp" does not exist\nLINE 1: select * from serial_barcode_table order by entry_added_time...\n                                                    ^\n\n'
2021-02-02 16:30:00,562 (22328/MainThread) pgcli.pgexecute ERROR - sql: 'select * from serial_barcode_table desc limit 10', error: SyntaxError('syntax error at or near "desc"\nLINE 1: select * from serial_barcode_table desc limit 10\n                                           ^\n')
2021-02-02 16:30:00,562 (22328/MainThread) pgcli.pgexecute ERROR - traceback: 'Traceback (most recent call last):\n  File "/usr/local/Cellar/pgcli/3.1.0/libexec/lib/python3.9/site-packages/pgcli/pgexecute.py", line 409, in run\n    yield self.execute_normal_sql(sql) + (sql, True, False)\n  File "/usr/local/Cellar/pgcli/3.1.0/libexec/lib/python3.9/site-packages/pgcli/pgexecute.py", line 444, in execute_normal_sql\n    cur.execute(split_sql)\npsycopg2.errors.SyntaxError: syntax error at or near "desc"\nLINE 1: select * from serial_barcode_table desc limit 10\n                                           ^\n\n'
2021-02-02 16:31:17,000 (22328/MainThread) pgcli.pgexecute ERROR - sql: 'SELECT * FROM serial_barcode_table WHERE serial_id = addd5bec-648f-11eb-ab8f-b3d65d712e7c', error: SyntaxError('syntax error at or near "f"\nLINE 1: ...erial_barcode_table WHERE serial_id = addd5bec-648f-11eb-ab8...\n                                                             ^\n')
2021-02-02 16:31:17,000 (22328/MainThread) pgcli.pgexecute ERROR - traceback: 'Traceback (most recent call last):\n  File "/usr/local/Cellar/pgcli/3.1.0/libexec/lib/python3.9/site-packages/pgcli/pgexecute.py", line 409, in run\n    yield self.execute_normal_sql(sql) + (sql, True, False)\n  File "/usr/local/Cellar/pgcli/3.1.0/libexec/lib/python3.9/site-packages/pgcli/pgexecute.py", line 444, in execute_normal_sql\n    cur.execute(split_sql)\npsycopg2.errors.SyntaxError: syntax error at or near "f"\nLINE 1: ...erial_barcode_table WHERE serial_id = addd5bec-648f-11eb-ab8...\n                                                             ^\n\n'
